<robot name="mearm">
  <link name="world" />

  <link name="base">
   <visual>
     <geometry>
       <cylinder length="0.6" radius="0.2" />
     </geometry>
   </visual>
 </link>

  <link name="link1">
   <visual>
     <geometry>
       <box size="0.6 0.1 0.2" />
     </geometry>
   </visual>
 </link>

  <joint name="base" type="continuous">
    <parent link="world"/>
    <child link="base"/>
    <axis xyz="0 0 1"/>
    <origin xyz="0 0 0" rpy="0 0 0"/>
  </joint>

  <joint name="left" type="continuous">
    <parent link="base"/>
    <child link="link1"/>
    <origin xyz="0 0 0.4" rpy="0 0 3.1416"/>
  </joint>
</robot>