<robot name="mearm">
  <link name="world" />

  <link name="link1">
   <inertial>
     <origin xyz="0 0 0.5" rpy="0 0 0"/>
     <mass value="1"/>
     <inertia ixx="100"  ixy="0"  ixz="0" iyy="100" iyz="0" izz="100" />
   </inertial>

   <visual>
     <origin xyz="0 0 0" rpy="0 0 0" />
     <geometry>
       <box size="1 1 1" />
     </geometry>
     <material name="Cyan">
       <color rgba="0 1.0 1.0 1.0"/>
     </material>
   </visual>

   <collision>
     <origin xyz="0 0 0" rpy="0 0 0"/>
     <geometry>
       <cylinder radius="1" length="0.5"/>
     </geometry>
   </collision>
 </link>

  <link name="link2">
   <inertial>
     <origin xyz="0 0 0.5" rpy="0 0 0"/>
     <mass value="1"/>
     <inertia ixx="100"  ixy="0"  ixz="0" iyy="100" iyz="0" izz="100" />
   </inertial>

   <visual>
     <origin xyz="0 0 0" rpy="0 0 0" />
     <geometry>
       <box size="2 2 2" />
     </geometry>

   </visual>

   <collision>
     <origin xyz="0 0 0" rpy="0 0 0"/>
     <geometry>
       <cylinder radius="1" length="0.5"/>
     </geometry>
   </collision>
 </link>

  <joint name="base" type="continuous">
    <parent link="world"/>
    <child link="link1"/>
    <axis xyz="0 0 1"/>
    <origin xyz="0 0 0" rpy="0 0 0"/>
  </joint>

  <joint name="left" type="continuous">
    <parent link="link1"/>
    <child link="link2"/>
    <origin xyz="0 0 0.5" rpy="0 0 3.1416"/>
  </joint>
</robot>